Workbook

Sheet MyWells Drilling Comp
A1: NOOP Document Date | B1: FWR Document Date | C1: PAC Name | D1: Region Name | E1: Field Name | F1: Well Name | G1: Well Type | H1: Rig Name | I1: Rig Type | J1: Water Depth (m) | K1: Total Well Depth MD Plan (m) | L1: Total Well Depth TVD Plan (m) | M1: AFE Cost Dry (usd) | N1: AFE Cost Success (usd) | O1: AFE Days Dry | P1: AFE Days Success | Q1: AFE Cost (usd) | R1: AFE Days | S1: Special Status | T1: Alternative Well Name | U1: Tree Type | V1: Spud Date | W1: Well Start Date Time | X1: Well End Date Time | Y1: Meterage Drilled (m) | Z1: Water Depth Category | AA1: Total Well Depth MD Actual (m) | AB1: Total Well Depth TVD Actual (m) | AC1: Final Cost Dry (usd) | AD1: Final Cost Success (usd) | AE1: Final Days Dry | AF1: Final Days Success | AG1: Final Cost (usd) | AH1: Final Days | AI1: Well NPT Percentage WOW (%) | AJ1: Well NPT Percentage (%) | AK1: Drilling Min Standard | AL1: DMS | AM1: Plan DDPTF (days/1000ft) | AN1: Plan DDPTF | AO1: Plan DCPF (usd/ft) | AP1: Plan DCPF | AQ1: Plan WCPF (usd/ft) | AR1: Plan WCPF | AS1: Actual DDPTF (days/1000ft) | AT1: Actual DDPTF | AU1: Actual DCPF (usd/ft) | AV1: Actual DCPF | AW1: Actual WCPF (usd/ft) | AX1: Actual WCPF | AY1: Completion Days Plan | AZ1: Completion Cost Plan | BA1: Completion Min Standard | BB1: Plan CDPTF (days/1000ft) | BC1: Plan CCPF (usd/ft) | BD1: Completion Days Actual | BE1: Completion Cost Actual | BF1: Actual CDPTF (days/1000ft) | BG1: Actual CCPF (usd/ft) | BH1: Producing Formation | BI1: Pressure Temperature | BJ1: Completion Type | BK1: Smart Well | BL1: ESP | BM1: Tubing Size (inch) | BN1: Zones | BO1: Number Of String | BP1: Tubing Material | BQ1: Sand Control Length (ft) | BR1: PDG | BS1: OH Inflow Control | BT1: Completion Material | BU1: Completion Fluid Weight (ppg) | BV1: Completion Fluid Type | BW1: Chemical Injection Valve | BX1: Intelligent Gas Lift | BY1: Availability
A2: 44992 | B2: 45232 | C2: VESTIGO | D2: PM | E2: LARUT | F2: LARUT A-26ST2 | G2: APPRAISAL CUM DEV/DEVELOPMENT | H2: SAPURA BERANI | I2: TENDER ASSISTED DRILLING RIG (TADR) | J2: 60 | K2: 4127.49 | L2: 2338.05 | M2: N/A | N2: N/A | O2: N/A | P2: N/A | Q2: 6560000 | R2: 14.29 | S2: NO | T2: N/A | U2: DRY TREE | V2: 45163 | W2: 45162.792 | X2: 45176.208 | Y2: 4026.63 | Z2: SHALLOW WATER | AA2: 4121.5 | AB2: 2333.55 | AC2: N/A | AD2: N/A | AE2: N/A | AF2: N/A | AG2: 4668369 | AH2: 13.42 | AI2: 8.01 | AJ2: 8.01 | AK2: SW DEV ST 2HS MONOBORE | AL2: SW DEV ST 2HS | AM2: Yes | AN2: 2.4 | AO2: Yes | AP2: 795 | AQ2: Yes | AR2: 1200 | AS2: yes | AT2: 1.3 | AU2: yes | AV2: 325 | AW2: yes | AX2: 454 | BD2: 1.81 | BE2: 1318987.4 | BH2: SANDSTONE | BI2: NORMAL | BJ2: CASED HOLE CEMENTED MONOBORE | BK2: NO | BL2: NO | BM2: 3-1/2" | BN2: 1.0 | BO2: SINGLE | BP2: L80 13CR | BQ2: 65.62 | BR2: False | BT2: L80 13CR | BU2: 6.8 | BV2: BASE OIL/DIESEL | BW2: NO | BX2: NO | BY2: =IF(COUNTIF('Data Upload-prod'!E:E,F2)=0,"Missing","Exist") -> Exist
A3: 44992 | B3: 45294 | C3: VESTIGO | D3: PM | E3: LARUT | F3: LARUT-A09ST1 | G3: APPRAISAL CUM DEV/DEVELOPMENT | H3: SAPURA BERANI | I3: TENDER ASSISTED DRILLING RIG (TADR) | J3: 60 | K3: 3407.5 | L3: 1961.86 | M3: N/A | N3: N/A | O3: N/A | P3: N/A | Q3: 7120000 | R3: 17.85 | S3: NO | T3: N/A | U3: DRY TREE | V3: 45220 | W3: 45220.062 | X3: 45244.104 | Y3: 3665.13 | Z3: SHALLOW WATER | AA3: 3760 | AB3: 2047.8 | AC3: N/A | AD3: N/A | AE3: N/A | AF3: N/A | AG3: 4734531 | AH3: 12.6 | AI3: 0 | AJ3: 0 | AK3: SW DEV ST 2HS MONOBORE | AL3: SW DEV ST 2HS | AM3: Yes | AN3: 2.4 | AO3: Yes | AP3: 795 | AQ3: Yes | AR3: 1200 | AS3: yes | AT3: 1.18 | AU3: yes | AV3: 329 | AW3: yes | AX3: 444 | BD3: 1.72 | BE3: 1220042.8 | BH3: SANDSTONE | BI3: NORMAL | BJ3: CASED HOLE CEMENTED MONOBORE | BK3: NO | BL3: NO | BM3: 3-1/2" | BN3: 1.0 | BO3: SINGLE | BP3: L80 | BQ3: 72.182 | BR3: False | BT3: L80 | BU3: 6.8 | BV3: BASE OIL/DIESEL | BW3: NO | BX3: NO | BY3: =IF(COUNTIF('Data Upload-prod'!E:E,F3)=0,"Missing","Exist") -> Exist
A4: 44992 | B4: 45251 | C4: VESTIGO | D4: PM | E4: LARUT | F4: LARUT-A29ST2 | G4: APPRAISAL CUM DEV/DEVELOPMENT | H4: SAPURA BERANI | I4: TENDER ASSISTED DRILLING RIG (TADR) | J4: 60 | K4: 3003.4 | L4: 2625.4 | M4: N/A | N4: N/A | O4: N/A | P4: N/A | Q4: 6779320 | R4: 13.52 | S4: NO | T4: N/A | U4: DRY TREE | V4: 45146 | W4: 45144.792 | X4: 45191.25 | Y4: 2871.13 | Z4: SHALLOW WATER | AA4: 2966 | AB4: 2622.8 | AC4: N/A | AD4: N/A | AE4: N/A | AF4: N/A | AG4: 5474865 | AH4: 16 | AI4: 34.32 | AJ4: 34.32 | AK4: SW DEV ST 2HS MONOBORE | AL4: SW DEV ST 2HS | AM4: Yes | AN4: 2.4 | AO4: Yes | AP4: 795 | AQ4: Yes | AR4: 1200 | AS4: yes | AT4: 2.43 | AU4: yes | AV4: 601 | AW4: yes | AX4: 830 | BD4: 1.34 | BE4: 1326979.4 | BH4: SANDSTONE | BI4: NORMAL | BJ4: CASED HOLE CEMENTED MONOBORE | BK4: NO | BL4: NO | BM4: 3-1/2" | BN4: 1.0 | BO4: SINGLE | BP4: L80 13CR | BQ4: 131.24 | BR4: False | BT4: L80 13CR | BU4: 6.8 | BV4: BASE OIL/DIESEL | BW4: NO | BX4: NO | BY4: =IF(COUNTIF('Data Upload-prod'!E:E,F4)=0,"Missing","Exist") -> Exist
A5: 44992 | B5: 45161 | C5: VESTIGO | D5: PM | E5: LARUT | F5: LARUT-A24 | G5: APPRAISAL CUM DEV/DEVELOPMENT | H5: SAPURA BERANI | I5: TENDER ASSISTED DRILLING RIG (TADR) | J5: 60 | K5: 2292.82 | L5: 1977.19 | M5: N/A | N5: N/A | O5: N/A | P5: N/A | Q5: 4563572.6 | R5: 9.51 | S5: SIDETRACK | T5: N/A | U5: DRY TREE | V5: 45105 | W5: 45105.292 | X5: 45115 | Y5: 2200.13 | Z5: SHALLOW WATER | AA5: 2295 | AB5: 1980.27 | AC5: N/A | AD5: N/A | AE5: N/A | AF5: N/A | AG5: 3572118 | AH5: 9.71 | AI5: 2.15 | AJ5: 2.15 | AK5: SW DEV ST 2HS MONOBORE | AL5: SW DEV ST 2HS | AM5: Yes | AN5: 2.4 | AO5: Yes | AP5: 795 | AQ5: Yes | AR5: 1200 | AS5: yes | AT5: 1.88 | AU5: yes | AV5: 484 | AW5: yes | AX5: 693 | BD5: 1.73 | BE5: 1081149.6 | BH5: SANDSTONE | BI5: NORMAL | BJ5: CASED HOLE CEMENTED MONOBORE | BK5: NO | BL5: NO | BM5: 3-1/2" | BN5: 1.0 | BO5: SINGLE | BP5: L80 | BQ5: 55.777 | BR5: False | BT5: L80 | BU5: 6.8 | BV5: BASE OIL/DIESEL | BW5: NO | BX5: NO | BY5: =IF(COUNTIF('Data Upload-prod'!E:E,F5)=0,"Missing","Exist") -> Exist
A6: 44981 | B6: 45310 | C6: VESTIGO | D6: PM | E6: LARUT | F6: LARUT-A01ST1 | G6: APPRAISAL CUM DEV/DEVELOPMENT | H6: SAPURA BERANI | I6: TENDER ASSISTED DRILLING RIG (TADR) | J6: 60 | K6: 3914.35 | L6: 2534.7 | M6: N/A | N6: N/A | O6: N/A | P6: N/A | Q6: 8235192 | R6: 17.9 | S6: NO | T6: N/A | U6: DRY TREE | V6: 45205 | W6: 45203.354 | X6: 45252.854 | Y6: 3138.13 | Z6: SHALLOW WATER | AA6: 3233 | AB6: 2511.69 | AC6: N/A | AD6: N/A | AE6: N/A | AF6: N/A | AG6: 8072116 | AH6: 25.46 | AI6: 12.07 | AJ6: 12.07 | AK6: SW DEV ST 2HS OHPDL | AL6: SW DEV ST 2HS | AM6: Yes | AN6: 2.4 | AO6: Yes | AP6: 795 | AQ6: Yes | AR6: 1400 | AS6: yes | AT6: 2.41 | AU6: yes | AV6: 725 | AW6: yes | AX6: 1014 | BD6: 5.48 | BE6: 2303835.7 | BH6: SANDSTONE | BI6: NORMAL | BJ6: OPEN HOLE PREDRILLED LINER | BK6: NO | BL6: NO | BM6: 3-1/2" | BN6: 1.0 | BO6: SINGLE | BP6: L80 13CR | BQ6: 207.51997 | BR6: False | BT6: L80 13CR | BU6: 9.2 | BV6: KCL | BW6: NO | BX6: NO | BY6: =IF(COUNTIF('Data Upload-prod'!E:E,F6)=0,"Missing","Exist") -> Exist
A7: 44981 | B7: 45239 | C7: VESTIGO | D7: PM | E7: LARUT | F7: LARUT-A30ST1 | G7: APPRAISAL CUM DEV/DEVELOPMENT | H7: SAPURA BERANI | I7: TENDER ASSISTED DRILLING RIG (TADR) | J7: 60 | K7: 3253.5 | L7: 1981.75 | M7: N/A | N7: N/A | O7: N/A | P7: N/A | Q7: 5350000 | R7: 11.62 | S7: NO | T7: N/A | U7: DRY TREE | V7: 45140 | W7: 45138.354 | X7: 45180.917 | Y7: 3310.13 | Z7: SHALLOW WATER | AA7: 3405 | AB7: 2042.65 | AC7: N/A | AD7: N/A | AE7: N/A | AF7: N/A | AG7: 3884000 | AH7: 11.15 | AI7: 1.68 | AJ7: 1.68 | AK7: SW DEV ST 2HS MONOBORE | AL7: SW DEV ST 2HS | AM7: Yes | AN7: 2.4 | AO7: Yes | AP7: 795 | AQ7: Yes | AR7: 1200 | AS7: yes | AT7: 1.4 | AU7: yes | AV7: 366 | AW7: yes | AX7: 489 | BD7: 1.45 | BE7: 977143.36 | BH7: SANDSTONE | BI7: NORMAL | BJ7: CASED HOLE CEMENTED MONOBORE | BK7: NO | BL7: NO | BM7: 3-1/2" | BN7: 1.0 | BO7: SINGLE | BP7: L80 | BQ7: 141.083 | BR7: False | BT7: L80 | BU7: 6.8 | BV7: BASE OIL/DIESEL | BW7: NO | BX7: NO | BY7: =IF(COUNTIF('Data Upload-prod'!E:E,F7)=0,"Missing","Exist") -> Exist
A8: 44981 | B8: 45273 | C8: VESTIGO | D8: PM | E8: LARUT | F8: LARUT A-36ST1 | G8: APPRAISAL CUM DEV/DEVELOPMENT | H8: SAPURA BERANI | I8: TENDER ASSISTED DRILLING RIG (TADR) | J8: 60 | K8: 4156.72 | L8: 2171.3 | M8: N/A | N8: N/A | O8: N/A | P8: N/A | Q8: 7175927 | R8: 15.48 | S8: NO | T8: N/A | U8: DRY TREE | V8: 45196 | W8: 45079.125 | X8: 45237.792 | Y8: 4161.13 | Z8: SHALLOW WATER | AA8: 4256 | AB8: 2205.85 | AC8: N/A | AD8: N/A | AE8: N/A | AF8: N/A | AG8: 7033425 | AH8: 21.64 | AI8: 7.51 | AJ8: 7.51 | AK8: SW DEV C3 MONOBORE | AL8: SW DEV C3 | AM8: Yes | AN8: 2.2 | AO8: Yes | AP8: 915 | AQ8: Yes | AR8: 1290 | AS8: yes | AT8: 1.64 | AU8: yes | AV8: 458 | AW8: yes | AX8: 534 | BD8: 1.69 | BE8: 993710.05 | BH8: SANDSTONE | BI8: NORMAL | BJ8: CASED HOLE CEMENTED MONOBORE | BK8: NO | BL8: NO | BM8: 3-1/2" | BN8: 1.0 | BO8: SINGLE | BP8: L80 | BQ8: 108.273 | BR8: False | BT8: L80 | BU8: 6.8 | BV8: BASE OIL/DIESEL | BW8: NO | BX8: NO | BY8: =IF(COUNTIF('Data Upload-prod'!E:E,F8)=0,"Missing","Exist") -> Exist
A9: 44980 | B9: 45251 | C9: VESTIGO | D9: PM | E9: LARUT | F9: LARUT-A23ST1 | G9: APPRAISAL CUM DEV/DEVELOPMENT | H9: SAPURA BERANI | I9: TENDER ASSISTED DRILLING RIG (TADR) | J9: 60 | K9: 3198.27 | L9: 2060.55 | M9: N/A | N9: N/A | O9: N/A | P9: N/A | Q9: 5184350 | R9: 11.24 | S9: NO | T9: N/A | U9: DRY TREE | V9: 45152 | W9: 45151.104 | X9: 45195.635 | Y9: 3005.13 | Z9: SHALLOW WATER | AA9: 3100 | AB9: 2097.55 | AC9: N/A | AD9: N/A | AE9: N/A | AF9: N/A | AG9: 3886398 | AH9: 10.55 | AI9: 5.53 | AJ9: 5.53 | AK9: SW DEV ST 2HS MONOBORE | AL9: SW DEV ST 2HS | AM9: Yes | AN9: 2.4 | AO9: Yes | AP9: 795 | AQ9: Yes | AR9: 1200 | AS9: yes | AT9: 1.44 | AU9: yes | AV9: 392 | AW9: yes | AX9: 532 | BD9: 1.4 | BE9: 889555.54 | BH9: SANDSTONE | BI9: NORMAL | BJ9: CASED HOLE CEMENTED MONOBORE | BK9: NO | BL9: NO | BM9: 3-1/2" | BN9: 1.0 | BO9: SINGLE | BP9: L80 | BQ9: 62.339 | BR9: False | BT9: L80 | BU9: 6.8 | BV9: BASE OIL/DIESEL | BW9: NO | BX9: NO | BY9: =IF(COUNTIF('Data Upload-prod'!E:E,F9)=0,"Missing","Exist") -> Exist
A10: 44966 | B10: 45196 | C10: VESTIGO | D10: PM | E10: LARUT | F10: LARUT A-35 | G10: APPRAISAL CUM DEV/DEVELOPMENT | H10: SAPURA BERANI | I10: TENDER ASSISTED DRILLING RIG (TADR) | J10: 60 | K10: 5658 | L10: 2334.8 | M10: N/A | N10: N/A | O10: N/A | P10: N/A | Q10: 9780000 | R10: 20.94 | S10: NO | T10: N/A | U10: DRY TREE | V10: 45076 | W10: 45075.917 | X10: 45138.354 | Y10: 5526.13 | Z10: SHALLOW WATER | AA10: 5621 | AB10: 2317 | AC10: N/A | AD10: N/A | AE10: N/A | AF10: N/A | AG10: 11405366 | AH10: 37.5 | AI10: 0.34 | AJ10: 0.34 | AK10: SW DEV C3 MONOBORE | AL10: SW DEV C3 | AM10: Yes | AN10: 2.2 | AO10: Yes | AP10: 915 | AQ10: Yes | AR10: 1290 | AS10: yes | AT10: 1.71 | AU10: yes | AV10: 432 | AW10: yes | AX10: 529 | BD10: 2.6 | BE10: 1866911.1 | BH10: SANDSTONE | BI10: NORMAL | BJ10: CASED HOLE CEMENTED MONOBORE | BK10: NO | BL10: NO | BM10: 3-1/2" | BN10: 1.0 | BO10: SINGLE | BP10: L80 | BQ10: 42.653 | BR10: False | BT10: L80 | BU10: 6.8 | BV10: BASE OIL/DIESEL | BW10: NO | BX10: NO | BY10: =IF(COUNTIF('Data Upload-prod'!E:E,F10)=0,"Missing","Exist") -> Exist
A11: 44966 | B11: 45251 | C11: VESTIGO | D11: PM | E11: LARUT | F11: LARUT-A31ST2 | G11: APPRAISAL CUM DEV/DEVELOPMENT | H11: SAPURA BERANI | I11: TENDER ASSISTED DRILLING RIG (TADR) | J11: 60 | K11: 3198.27 | L11: 2060.55 | M11: N/A | N11: N/A | O11: N/A | P11: N/A | Q11: 5184350 | R11: 11.24 | S11: RE-SPUD | T11: N/A | U11: DRY TREE | V11: 45152 | W11: 45151 | X11: 45195 | Y11: 3005.13 | Z11: SHALLOW WATER | AA11: 3100 | AB11: 2097.43 | AC11: N/A | AD11: N/A | AE11: N/A | AF11: N/A | AG11: 3886398 | AH11: 10.55 | AI11: 5.5 | AJ11: 5.5 | AK11: SW DEV ST 2HS OHPDL | AL11: SW DEV ST 2HS | AM11: Yes | AN11: 2.4 | AO11: Yes | AP11: 795 | AQ11: Yes | AR11: 1400 | AS11: yes | AT11: 2.7 | AU11: yes | AV11: 709 | AW11: yes | AX11: 917 | BD11: 7.75 | BE11: 3082902.8 | BH11: SANDSTONE | BI11: NORMAL | BJ11: OPEN HOLE PREDRILLED LINER | BK11: NO | BL11: NO | BM11: 3-1/2" | BN11: 1.0 | BO11: SINGLE | BP11: L80 13CR | BQ11: 823.28821 | BR11: False | BT11: L80 13CR | BU11: 9.2 | BV11: KCL | BW11: NO | BX11: NO | BY11: =IF(COUNTIF('Data Upload-prod'!E:E,F11)=0,"Missing","Exist") -> Exist
A12: 44966 | B12: 45176 | C12: VESTIGO | D12: PM | E12: LARUT | F12: LARUT A-34 | G12: APPRAISAL CUM DEV/DEVELOPMENT | H12: SAPURA BERANI | I12: TENDER ASSISTED DRILLING RIG (TADR) | J12: 60 | K12: 4112.23 | L12: 2024.08 | M12: N/A | N12: N/A | O12: N/A | P12: N/A | Q12: 8214591 | R12: 17.58 | S12: NO | T12: N/A | U12: DRY TREE | V12: 45069 | W12: 45067.75 | X12: 45120 | Y12: 3930.13 | Z12: SHALLOW WATER | AA12: 4025 | AB12: 1998.44 | AC12: N/A | AD12: N/A | AE12: N/A | AF12: N/A | AG12: 6690870 | AH12: 21.57 | AI12: 2.08 | AJ12: 2.08 | AK12: SW DEV C3 MONOBORE | AL12: SW DEV C3 | AM12: Yes | AN12: 2.2 | AO12: Yes | AP12: 915 | AQ12: Yes | AR12: 1290 | AS12: yes | AT12: 1.63 | AU12: yes | AV12: 413 | AW12: yes | AX12: 507 | BD12: 2 | BE12: 1233995 | BH12: SANDSTONE | BI12: NORMAL | BJ12: CASED HOLE CEMENTED MONOBORE | BK12: NO | BL12: NO | BM12: 3-1/2" | BN12: 1.0 | BO12: SINGLE | BP12: L80 | BQ12: 108.273 | BR12: False | BT12: L80 | BU12: 6.8 | BV12: BASE OIL/DIESEL | BW12: NO | BX12: NO | BY12: =IF(COUNTIF('Data Upload-prod'!E:E,F12)=0,"Missing","Exist") -> Exist
A13: 43599 | B13: 43747 | C13: VESTIGO | D13: SK | E13: ANJUNG KECIL | F13: AJK-A2ST1 | G13: APPRAISAL CUM DEV/DEVELOPMENT | H13: BORR MIST | I13: JACK UP | J13: 70.5 | K13: 2504 | L13: 1713 | M13: N/A | N13: N/A | O13: N/A | P13: N/A | Q13: 8100000 | R13: 20.5 | S13: NO | T13: N/A | U13: DRY TREE | V13: 43658 | W13: 43615.75 | X13: 43708.021 | Y13: 2439.35 | Z13: SHALLOW WATER | AA13: 2545 | AB13: 1712 | AC13: N/A | AD13: N/A | AE13: N/A | AF13: N/A | AG13: 6081416 | AH13: 21.14 | AI13: 6.6 | AJ13: 6.6 | AK13: SW DEV C4 OHSAS/OHPDL | AL13: SW DEV C4 | AM13: Yes | AN13: 2.5 | AO13: Yes | AP13: 1010 | AQ13: Yes | AR13: 1705 | AS13: yes | AT13: 1.49 | AU13: yes | AV13: 383 | AW13: yes | AX13: 728 | BD13: 6.5 | BE13: 2155737 | BH13: CARBONATE | BI13: NORMAL | BJ13: OPEN HOLE STAND ALONE SCREEN | BK13: NO | BL13: 1 | BM13: 3-1/2" | BN13: 1.0 | BO13: SINGLE | BP13: L80 | BQ13: 187.37791 | BR13: False | BS13: ICD | BT13: L80 | BU13: 8.6 | BV13: SEAWATER/DRILLWATER | BW13: NO | BX13: NO | BY13: =IF(COUNTIF('Data Upload-prod'!E:E,F13)=0,"Missing","Exist") -> Exist
A14: 43592 | B14: 43720 | C14: PCSB | D14: SK | E14: ANJUNG | F14: ANJUNG-A3 | G14: APPRAISAL CUM DEV/DEVELOPMENT | H14: NAGA-2 | I14: JACK UP | J14: 76 | K14: 2364.06 | L14: 1974.91 | M14: N/A | N14: N/A | O14: N/A | P14: N/A | Q14: 15765612 | R14: 44.83 | S14: NO | T14: N/A | U14: DRY TREE | V14: 43628 | W14: 43627.25 | X14: 43690.271 | Y14: 2227.92 | Z14: SHALLOW WATER | AA14: 2347.7 | AB14: 1976.89 | AC14: N/A | AD14: N/A | AE14: N/A | AF14: N/A | AG14: 15622646 | AH14: 43.3 | AI14: 13.11 | AJ14: 13.11 | AK14: SW DEV C4 OHPDL | AL14: SW DEV C4 | AM14: Yes | AN14: 2.5 | AO14: Yes | AP14: 1010 | AQ14: Yes | AR14: 1705 | AS14: 2.34 | AT14: 2.34 | AU14: 747 | AV14: 747 | AW14: 1802 | AX14: 1802 | BD14: 12.65 | BE14: 3107335.5 | BH14: CARBONATE | BI14: NORMAL | BJ14: OPEN HOLE PREDRILLED LINER | BK14: NO | BL14: NO | BM14: 7" | BN14: 1.0 | BO14: SINGLE | BP14: L80 13CR | BQ14: 0 | BR14: True | BT14: SUPER 13CR | BU14: 10.3 | BV14: NACOOH | BW14: NO | BX14: NO | BY14: =IF(COUNTIF('Data Upload-prod'!E:E,F14)=0,"Missing","Exist") -> Exist
A15: 43369 | B15: 43546 | C15: SHELL | D15: SB | E15: GEMILANG | F15: GEMILANG-1 | G15: EXPLORATION/APPRAISAL | H15: WEST CAPELLA | I15: DRILLSHIP | J15: 1022.25 | K15: 2885.71 | L15: 2693.69 | M15: 23400000 | N15: 31480000 | O15: 34.2 | P15: 45.3 | Q15: N/A | R15: N/A | S15: NO | T15: N/A | U15: N/A | V15: 43445 | W15: 43415.875 | X15: 43461.875 | Y15: 1838.46 | Z15: DEEP WATER | AA15: 2885.71 | AB15: 2668.7 | AC15: N/A | AD15: 31500000 | AE15: N/A | AF15: 45.3 | AG15: N/A | AH15: N/A | AI15: 11.65 | AJ15: 11.65 | AK15: No DMS category. Having value but not sure refering which version | AL15: No | AM15: No | AO15: No | AQ15: No | AS15: No | AU15: No | AW15: No | BY15: =IF(COUNTIF('Data Upload-prod'!E:E,F15)=0,"Missing","Exist") -> Exist
A16: 43333 | B16: 43462 | C16: REPSOL | D16: PM | E16: BUNGA ORKID | F16: BOB-9(J) | G16: APPRAISAL CUM DEV/DEVELOPMENT | H16: PVD-3 | I16: JACK UP | J16: 54.6 | K16: 4530.1 | L16: 2190 | M16: N/A | N16: N/A | O16: N/A | P16: N/A | Q16: 14900000 | R16: 42.14 | S16: NO | T16: N/A | U16: DRY TREE | V16: 43354 | W16: 43347.792 | X16: 43411.062 | Y16: 4652.6 | Z16: SHALLOW WATER | AA16: 4745 | AB16: 2222.84 | AC16: N/A | AD16: N/A | AE16: N/A | AF16: N/A | AG16: 13977440 | AH16: 63.27 | AI16: 33.55 | AJ16: 19.07 | AK16: No DMS category | AL16: No | AM16: No | AO16: No | AQ16: No | AS16: No | AU16: No | AW16: No | BD16: 18 | BE16: 4000000 | BH16: SANDSTONE | BI16: NORMAL | BJ16: OPEN HOLE PREDRILLED LINER | BK16: NO | BL16: NO | BM16: 3-1/2" | BN16: 1.0 | BO16: SINGLE | BP16: L80 13CR | BQ16: 2237.5328 | BR16: True | BS16: NONE | BT16: L80 13CR | BU16: 8.6 | BV16: KCL | BW16: NO | BX16: NO | BY16: =IF(COUNTIF('Data Upload-prod'!E:E,F16)=0,"Missing","Exist") -> Exist
A17: 43314 | B17: N/A | C17: REPSOL | D17: PM | E17: BUNGA PAKMA | F17: BPA-6 | G17: APPRAISAL CUM DEV/DEVELOPMENT | H17: PVD-3 | I17: JACK UP | J17: 58 | K17: 4278 | L17: 3029 | M17: N/A | N17: N/A | O17: N/A | P17: N/A | Q17: 8366634 | R17: 22 | S17: NO | T17: N/A | U17: DRY TREE | V17: 43326 | W17: 43324.833 | X17: 43346 | Y17: 4177.13 | Z17: SHALLOW WATER | AA17: 4278 | AB17: 3029 | AC17: N/A | AD17: N/A | AE17: N/A | AF17: N/A | AG17: 6700000 | AH17: 21.17 | AI17: 8.3 | AJ17: 8.3 | AK17: No DMS category | AL17: No | AM17: No | AO17: No | AQ17: No | AS17: No | AU17: No | AW17: No | BD17: 6.51 | BE17: 2629741 | BH17: SANDSTONE | BI17: NORMAL | BJ17: CASED HOLE CEMENTED MONOBORE | BK17: NO | BL17: NO | BM17: 5-1/2" | BN17: 1.0 | BO17: SINGLE | BP17: L80 13CR | BQ17: 63.976378 | BR17: True | BS17: NONE | BT17: L80 13CR | BU17: 6.84 | BV17: BASE OIL/DIESEL | BW17: NO | BX17: NO | BY17: =IF(COUNTIF('Data Upload-prod'!E:E,F17)=0,"Missing","Exist") -> Exist
A18: 43300 | B18: 43420 | C18: SHELL | D18: SK | E18: RERAMA | F18: RERAMA-1 | G18: EXPLORATION/APPRAISAL | H18: NAGA-7 | I18: JACK UP | J18: 60.65 | K18: 1829.02 | L18: 1430.36 | M18: 9517000 | N18: 13400000 | O18: 22.43 | P18: 30.29 | Q18: N/A | R18: N/A | S18: NO | T18: N/A | U18: N/A | V18: 43351 | W18: 43346.854 | X18: 43370.74 | Y18: 1376.1 | Z18: SHALLOW WATER | AA18: 1467.54 | AB18: 1467.54 | AC18: 5640000 | AD18: N/A | AE18: 23.89 | AF18: N/A | AG18: N/A | AH18: N/A | AI18: 4.23 | AJ18: 4.23 | AK18: No DMS category | AL18: No | AM18: No | AO18: No | AQ18: No | AS18: No | AU18: No | AW18: No | BY18: =IF(COUNTIF('Data Upload-prod'!E:E,F18)=0,"Missing","Exist") -> Exist
A19: 43268 | B19: 43334 | C19: REPSOL | D19: PM | E19: BUNGA PAKMA | F19: BPA-4 | G19: APPRAISAL CUM DEV/DEVELOPMENT | H19: PVD-3 | I19: JACK UP | J19: 58 | K19: 4887 | L19: 3353 | M19: N/A | N19: N/A | O19: N/A | P19: N/A | Q19: 14232446 | R19: 33.29 | S19: NO | T19: N/A | U19: DRY TREE | V19: 43269 | W19: 43269.396 | X19: 43324.833 | Y19: 4849.13 | Z19: SHALLOW WATER | AA19: 4950 | AB19: 3422 | AC19: N/A | AD19: N/A | AE19: N/A | AF19: N/A | AG19: 11240000 | AH19: 33.3 | AI19: 8.09 | AJ19: 8.03 | AK19: SW DEV C2 PM - MONOBORE | AL19: SW DEV C2 | AM19: Yes | AN19: 3.2 | AO19: Yes | AP19: 1300 | AQ19: Yes | AR19: 1600 | AS19: Yes | AT19: 1.97 | AU19: Yes | AV19: 669 | AW19: Yes | AX19: 757 | BD19: 6.57 | BE19: 1902000 | BH19: SANDSTONE | BI19: NORMAL | BJ19: CASED HOLE CEMENTED MONOBORE | BK19: NO | BL19: NO | BM19: 5-1/2" | BN19: 1.0 | BO19: SINGLE | BP19: L80 13CR | BQ19: 63.976378 | BR19: True | BS19: NONE | BT19: L80 13CR | BU19: 6.84 | BV19: BASE OIL/DIESEL | BW19: NO | BX19: NO | BY19: =IF(COUNTIF('Data Upload-prod'!E:E,F19)=0,"Missing","Exist") -> Exist
A20: 43201 | B20: 43286 | C20: REPSOL | D20: SB | E20: KINABALU | F20: KNDW-D08 | G20: APPRAISAL CUM DEV/DEVELOPMENT | H20: NAGA-5 | I20: JACK UP | J20: 54.25 | K20: 3801.89 | L20: 2426.7 | M20: N/A | N20: N/A | O20: N/A | P20: N/A | Q20: 14724389 | R20: 30.34 | S20: NO | T20: N/A | U20: N/A | V20: 43215 | W20: 43215.333 | X20: 43237.083 | Y20: 3806.77 | Z20: SHALLOW WATER | AA20: 3901.25 | AB20: 2425.78 | AC20: N/A | AD20: N/A | AE20: N/A | AF20: N/A | AG20: 9031731 | AH20: 21.75 | AI20: 1.3 | AJ20: 1.3 | AK20: No DMS category | AL20: No | AM20: No | AO20: No | AQ20: No | AS20: No | AU20: No | AW20: No | BY20: =IF(COUNTIF('Data Upload-prod'!E:E,F20)=0,"Missing","Exist") -> Exist
A21: 43191 | B21: 43286 | C21: REPSOL | D21: PM | E21: BUNGA PAKMA | F21: BPA-1 | G21: APPRAISAL CUM DEV/DEVELOPMENT | H21: PVD-3 | I21: JACK UP | J21: 58 | K21: 3268 | L21: 2947.1 | M21: N/A | N21: N/A | O21: N/A | P21: N/A | Q21: 12440000 | R21: 30.7 | S21: NO | T21: N/A | U21: N/A | V21: 43202 | W21: 43202 | X21: 43226 | Y21: 3154.13 | Z21: SHALLOW WATER | AA21: 3255 | AB21: 2926 | AC21: N/A | AD21: N/A | AE21: N/A | AF21: N/A | AG21: 8530528 | AH21: 24 | AI21: 14 | AJ21: 14 | AK21: No DMS category | AL21: No | AM21: No | AO21: No | AQ21: No | AS21: No | AU21: No | AW21: No | BY21: =IF(COUNTIF('Data Upload-prod'!E:E,F21)=0,"Missing","Exist") -> Exist
A22: 43188 | B22: 43276 | C22: PCSB | D22: SB | E22: SAMARANG | F22: SM-37ST | G22: APPRAISAL CUM DEV/DEVELOPMENT | H22: NAGA-3 | I22: JACK UP | J22: 47 | K22: 3049.38 | L22: 2295.03 | M22: N/A | N22: N/A | O22: N/A | P22: N/A | Q22: 10498894 | R22: 40.21 | S22: NO | T22: N/A | U22: DRY TREE | V22: 43224 | W22: 43224 | X22: 43240 | Y22: 2740.57 | Z22: SHALLOW WATER | AA22: 2822.31 | AB22: 2110.94 | AC22: N/A | AD22: N/A | AE22: N/A | AF22: N/A | AG22: 5170000 | AH22: 22.1 | AI22: 0.28 | AJ22: 0.28 | AK22: No DMS category | AL22: No | AM22: No | AO22: No | AQ22: No | AS22: No | AU22: No | AW22: No | BD22: 6.29 | BE22: 2046460 | BH22: SANDSTONE | BI22: NORMAL | BJ22: CASED HOLE | BK22: NO | BL22: NO | BM22: 3-1/2" | BN22: 5.0 | BO22: SINGLE | BP22: L80 | BQ22: 600 | BR22: False | BS22: NONE | BT22: 13CR | BU22: 8.5 | BV22: SEAWATER/DRILLWATER | BW22: NO | BX22: NO | BY22: =IF(COUNTIF('Data Upload-prod'!E:E,F22)=0,"Missing","Exist") -> Exist
A23: 43181 | B23: 43271 | C23: REPSOL | D23: SB | E23: KINABALU | F23: KNDW-D16 | G23: APPRAISAL CUM DEV/DEVELOPMENT | H23: NAGA-5 | I23: JACK UP | J23: 54.25 | K23: 2133.8 | L23: 1977.14 | M23: N/A | N23: N/A | O23: N/A | P23: N/A | Q23: 10567967 | R23: 21 | S23: NO | T23: N/A | U23: N/A | V23: 43200 | W23: 43199.583 | X23: 43214.375 | Y23: 2005.18 | Z23: SHALLOW WATER | AA23: 2099.66 | AB23: 1933.86 | AC23: N/A | AD23: N/A | AE23: N/A | AF23: N/A | AG23: 6043404 | AH23: 14.83 | AI23: 0.13 | AJ23: 0.13 | AK23: No DMS category | AL23: No | AM23: No | AO23: No | AQ23: No | AS23: No | AU23: No | AW23: No | BY23: =IF(COUNTIF('Data Upload-prod'!E:E,F23)=0,"Missing","Exist") -> Exist
A24: 43152 | B24: 43223 | C24: REPSOL | D24: SB | E24: KINABALU | F24: KNDW-D02 | G24: APPRAISAL CUM DEV/DEVELOPMENT | H24: NAGA-5 | I24: JACK UP | J24: 54.25 | K24: 4323.97 | L24: 3669.03 | M24: N/A | N24: N/A | O24: N/A | P24: N/A | Q24: 15840192 | R24: 36.98 | S24: NO | T24: N/A | U24: N/A | V24: 43168 | W24: 43167.583 | X24: 43199.542 | Y24: 4203.9 | Z24: SHALLOW WATER | AA24: 4298.38 | AB24: 3667.03 | AC24: N/A | AD24: N/A | AE24: N/A | AF24: N/A | AG24: 13783161 | AH24: 31.96 | AI24: 3.46 | AJ24: 3.46 | AK24: No DMS category | AL24: No | AM24: No | AO24: No | AQ24: No | AS24: No | AU24: No | AW24: No | BY24: =IF(COUNTIF('Data Upload-prod'!E:E,F24)=0,"Missing","Exist") -> Exist
A25: 43021 | B25: 43270 | C25: ROC OIL | D25: SK | E25: J4 | F25: J4-A09 | G25: APPRAISAL CUM DEV/DEVELOPMENT | H25: PERISAI PACIFIC-101 | I25: JACK UP | J25: 53.64 | K25: 1956.11 | L25: 1956.11 | M25: N/A | N25: N/A | O25: N/A | P25: N/A | Q25: 11610000 | R25: 24.48 | S25: NO | T25: N/A | U25: N/A | V25: 43101 | W25: 43100 | X25: 43209 | Y25: 2120.7 | Z25: SHALLOW WATER | AA25: 2217.31 | AB25: 1630.57 | AC25: N/A | AD25: N/A | AE25: N/A | AF25: N/A | AG25: 8668774 | AH25: 33.63 | AI25: 7.52 | AJ25: 7.24 | AK25: No DMS category | AL25: No | AM25: No | AO25: No | AQ25: No | AS25: No | AU25: No | AW25: No | BY25: =IF(COUNTIF('Data Upload-prod'!E:E,F25)=0,"Missing","Exist") -> Exist
A26: 42828 | B26: 43049 | C26: ROC OIL | D26: SK | E26: D21 | F26: D21-A7ST1 | G26: APPRAISAL CUM DEV/DEVELOPMENT | H26: PERISAI PACIFIC-101 | I26: JACK UP | J26: 50.59 | K26: 3913.44 | L26: 2294.18 | M26: N/A | N26: N/A | O26: N/A | P26: N/A | Q26: 11189579 | R26: 27.45 | S26: NO | T26: N/A | U26: N/A | V26: 42919 | W26: 42913.5 | X26: 42992 | Y26: 3817.13 | Z26: SHALLOW WATER | AA26: 3913.44 | AB26: 2294.26 | AC26: N/A | AD26: N/A | AE26: N/A | AF26: N/A | AG26: 14508177 | AH26: 47.83 | AI26: 25.72 | AJ26: 25.7 | AK26: No DMS category | AL26: No | AM26: No | AO26: No | AQ26: No | AS26: No | AU26: No | AW26: No | BY26: =IF(COUNTIF('Data Upload-prod'!E:E,F26)=0,"Missing","Exist") -> Exist
A27: 42826 | B27: 42989 | C27: REPSOL | D27: PM | E27: BUNGA ORKID | F27: NBO-4 | G27: EXPLORATION/APPRAISAL | H27: ENSCO-52 | I27: JACK UP | J27: 54.7 | K27: 4174 | L27: 2471 | M27: 25018081 | N27: 25018081 | O27: 70.26 | P27: 70.26 | Q27: N/A | R27: N/A | S27: SIDETRACK | T27: N/A | U27: N/A | V27: 42875.396 | W27: 42869.438 | X27: 42955.375 | Y27: 3145.3 | Z27: SHALLOW WATER | AA27: 3230 | AB27: 2009 | AC27: N/A | AD27: 20595074 | AE27: N/A | AF27: 54.94 | AG27: N/A | AH27: N/A | AI27: 13.27 | AJ27: 13.25 | AK27: No DMS category | AL27: No | AM27: No | AO27: No | AQ27: No | AS27: No | AU27: No | AW27: No | BY27: =IF(COUNTIF('Data Upload-prod'!E:E,F27)=0,"Missing","Exist") -> Exist
A28: 42821 | B28: 43052 | C28: ROC OIL | D28: SK | E28: D21 | F28: D21-P1 | G28: APPRAISAL CUM DEV/DEVELOPMENT | H28: PERISAI PACIFIC-101 | I28: JACK UP | J28: 50.59 | K28: 2796.71 | L28: 2183.18 | M28: N/A | N28: N/A | O28: N/A | P28: N/A | Q28: 11000000 | R28: 23.29 | S28: NO | T28: N/A | U28: N/A | V28: 42872.719 | W28: 42867.354 | X28: 42990.167 | Y28: 2677.23 | Z28: SHALLOW WATER | AA28: 2773.54 | AB28: 2158.06 | AC28: N/A | AD28: N/A | AE28: N/A | AF28: N/A | AG28: 10427402 | AH28: 29.15 | AI28: 10.25 | AJ28: 10.25 | AK28: No DMS category | AL28: No | AM28: No | AO28: No | AQ28: No | AS28: No | AU28: No | AW28: No | BY28: =IF(COUNTIF('Data Upload-prod'!E:E,F28)=0,"Missing","Exist") -> Exist
A29: 42769 | B29: 42907 | C29: PETROFAC | D29: PM | E29: WEST DESARU | F29: WD-A17ST1 | G29: APPRAISAL CUM DEV/DEVELOPMENT | H29: NAGA-5 | I29: JACK UP | J29: 65.8 | K29: 2830 | L29: 1604 | M29: N/A | N29: N/A | O29: N/A | P29: N/A | Q29: 7142000 | R29: 23.9 | S29: NO | T29: N/A | U29: DRY TREE | V29: 42859 | W29: 42859 | X29: 42881 | Y29: 2738.74 | Z29: SHALLOW WATER | AA29: 2848 | AB29: 1608 | AC29: N/A | AD29: N/A | AE29: N/A | AF29: N/A | AG29: 6940000 | AH29: 22.2 | AI29: 2.82 | AJ29: 2.82 | AK29: No DMS category | AL29: No | AM29: No | AO29: No | AQ29: No | AS29: No | AU29: No | AW29: No | BD29: 8.82 | BE29: 3317397.7 | BH29: SANDSTONE | BI29: NORMAL | BJ29: CASED HOLE | BK29: NO | BL29: NO | BM29: 2-7/8" | BN29: 1.0 | BO29: SINGLE | BP29: L80 13CR | BQ29: 0 | BR29: False | BT29: L80 13CR | BU29: 9.1 | BV29: NACL | BW29: NO | BX29: NO | BY29: =IF(COUNTIF('Data Upload-prod'!E:E,F29)=0,"Missing","Exist") -> Exist
A30: 42530 | B30: 42803 | C30: NOEX | D30: SK | E30: LAYANG | F30: LAYANG-2 | G30: APPRAISAL CUM DEV/DEVELOPMENT | H30: SAPURA BERANI | I30: TENDER ASSISTED DRILLING RIG (TADR) | J30: 87 | K30: 4028 | L30: 3635 | M30: N/A | N30: N/A | O30: N/A | P30: N/A | Q30: 23294644 | R30: 46.81 | S30: SIDETRACK | T30: N/A | U30: N/A | V30: 42586 | W30: 42586 | X30: 42742.5 | Y30: 4232.8 | Z30: SHALLOW WATER | AA30: 4350 | AB30: 3663 | AC30: N/A | AD30: N/A | AE30: N/A | AF30: N/A | AG30: 25292683 | AH30: 83.41 | AI30: 0.46 | AJ30: 0.46 | AK30: No DMS category | AL30: No | AM30: No | AO30: No | AQ30: No | AS30: No | AU30: No | AW30: No | BY30: =IF(COUNTIF('Data Upload-prod'!E:E,F30)=0,"Missing","Exist") -> Exist
A31: 42436 | B31: 42502 | C31: EMEPMI | D31: PM | E31: GUNTONG | F31: GUNTONG-C14ST1 | G31: APPRAISAL CUM DEV/DEVELOPMENT | H31: T-9 | I31: TENDER ASSISTED DRILLING RIG (TADR) | J31: 63.7 | K31: 2240 | L31: 1978 | M31: N/A | N31: N/A | O31: N/A | P31: N/A | Q31: 13600000 | R31: 24.6 | S31: SIDETRACK | T31: N/A | U31: N/A | V31: 42451 | W31: 42451 | X31: 42463 | Y31: 2143 | Z31: SHALLOW WATER | AA31: 2240 | AB31: 1978 | AC31: N/A | AD31: N/A | AE31: N/A | AF31: N/A | AG31: 11500000 | AH31: 13.6 | AI31: 3.5 | AJ31: 3.5 | AK31: No DMS category | AL31: No | AM31: No | AO31: No | AQ31: No | AS31: No | AU31: No | AW31: No | BY31: =IF(COUNTIF('Data Upload-prod'!E:E,F31)=0,"Missing","Exist") -> Exist
A32: 42412 | B32: 42481 | C32: EMEPMI | D32: PM | E32: GUNTONG | F32: GUNTONG-C05ST1 | G32: APPRAISAL CUM DEV/DEVELOPMENT | H32: T-9 | I32: TENDER ASSISTED DRILLING RIG (TADR) | J32: 63.7 | K32: 2565 | L32: 2021 | M32: N/A | N32: N/A | O32: N/A | P32: N/A | Q32: 19820000 | R32: 26 | S32: NO | T32: N/A | U32: N/A | V32: 42421 | W32: 42421 | X32: 42440 | Y32: 2470 | Z32: SHALLOW WATER | AA32: 2567 | AB32: 2021 | AC32: N/A | AD32: N/A | AE32: N/A | AF32: N/A | AG32: 11700000 | AH32: 19.25 | AI32: 0.78 | AJ32: 0.78 | AK32: No DMS category | AL32: No | AM32: No | AO32: No | AQ32: No | AS32: No | AU32: No | AW32: No | BY32: =IF(COUNTIF('Data Upload-prod'!E:E,F32)=0,"Missing","Exist") -> Exist
A33: 42338 | B33: 42424 | C33: EMEPMI | D33: PM | E33: GUNTONG | F33: GUNTONG-C10 | G33: APPRAISAL CUM DEV/DEVELOPMENT | H33: T-9 | I33: TENDER ASSISTED DRILLING RIG (TADR) | J33: 63.7 | K33: 3310 | L33: 1954 | M33: N/A | N33: N/A | O33: N/A | P33: N/A | Q33: 11600000 | R33: 21.1 | S33: SIDETRACK | T33: N/A | U33: N/A | V33: 42351.5 | W33: 42351.5 | X33: 42379 | Y33: 3208 | Z33: SHALLOW WATER | AA33: 3305 | AB33: 1948 | AC33: N/A | AD33: N/A | AE33: N/A | AF33: N/A | AG33: 9300000 | AH33: 21.04 | AI33: 12.7 | AJ33: 12.7 | AK33: No DMS category | AL33: No | AM33: No | AO33: No | AQ33: No | AS33: No | AU33: No | AW33: No | BY33: =IF(COUNTIF('Data Upload-prod'!E:E,F33)=0,"Missing","Exist") -> Exist
A34: 42237 | B34: 42314 | C34: PCSB | D34: SB | E34: SAMARANG | F34: SAMARANG EAST-1 | G34: EXPLORATION/APPRAISAL | H34: NAGA-4 | I34: JACK UP | J34: 10.06 | K34: 2900.94 | L34: 2232.25 | M34: 15563189 | N34: 15563189 | O34: 26.4 | P34: 26.4 | Q34: N/A | R34: N/A | S34: NO | T34: N/A | U34: N/A | V34: 42255.333 | W34: 42250 | X34: 42291 | Y34: 2982.81 | Z34: SHALLOW WATER | AA34: 3023.47 | AB34: 2262.72 | AC34: N/A | AD34: 15120935 | AE34: N/A | AF34: 37.17 | AG34: N/A | AH34: N/A | AI34: 5.38 | AJ34: 5.38 | AK34: No DMS category | AL34: No | AM34: No | AO34: No | AQ34: No | AS34: No | AU34: No | AW34: No | BY34: =IF(COUNTIF('Data Upload-prod'!E:E,F34)=0,"Missing","Exist") -> Exist
A35: 42026 | B35: 42229 | C35: PCSB | D35: SK | E35: BAYAN | F35: BAYAN-220 | G35: APPRAISAL CUM DEV/DEVELOPMENT | H35: TASHA | I35: JACK UP | J35: 29.26 | K35: 2282.84 | L35: 1427.92 | M35: N/A | N35: N/A | O35: N/A | P35: N/A | Q35: 20890000 | R35: 23.38 | S35: NO | T35: N/A | U35: DRY TREE | V35: 42131 | W35: 42130 | X35: 42192 | Y35: 2014.32 | Z35: SHALLOW WATER | AA35: 2093.57 | AB35: 1236.21 | AC35: N/A | AD35: N/A | AE35: N/A | AF35: N/A | AG35: 11194141 | AH35: 28.86 | AI35: 8.63 | AJ35: 5.91 | AK35: No DMS category | AL35: No | AM35: No | AO35: No | AQ35: No | AS35: No | AU35: No | AW35: No | BY35: =IF(COUNTIF('Data Upload-prod'!E:E,F35)=0,"Missing","Exist") -> Exist
A36: 41990 | B36: 42199 | C36: PCSB | D36: SK | E36: BAYAN | F36: BAYAN-221 | G36: APPRAISAL CUM DEV/DEVELOPMENT | H36: TASHA | I36: JACK UP | J36: 29.26 | K36: 2199.33 | L36: 1261.2 | M36: N/A | N36: N/A | O36: N/A | P36: N/A | Q36: 19106061 | R36: 26.2 | S36: SIDETRACK | T36: N/A | U36: N/A | V36: 42073 | W36: 42066 | X36: 42170 | Y36: 1776.29 | Z36: SHALLOW WATER | AA36: 1855.53 | AB36: 1256.63 | AC36: N/A | AD36: N/A | AE36: N/A | AF36: N/A | AG36: 16347000 | AH36: 31.9 | AI36: 41.7 | AJ36: 41.7 | AK36: No DMS category | AL36: No | AM36: No | AO36: No | AQ36: No | AS36: No | AU36: No | AW36: No | BY36: =IF(COUNTIF('Data Upload-prod'!E:E,F36)=0,"Missing","Exist") -> Exist
A37: 41978 | B37: 42173 | C37: PCSB | D37: SK | E37: BAYAN | F37: BAYAN-223 | G37: APPRAISAL CUM DEV/DEVELOPMENT | H37: TASHA | I37: JACK UP | J37: 29.26 | K37: 2582.14 | L37: 1360.26 | M37: N/A | N37: N/A | O37: N/A | P37: N/A | Q37: 20340000 | R37: 28 | S37: NO | T37: N/A | U37: DRY TREE | V37: 42053.375 | W37: 42050.198 | X37: 42110 | Y37: 2539.26 | Z37: SHALLOW WATER | AA37: 2615.15 | AB37: 1357.51 | AC37: N/A | AD37: N/A | AE37: N/A | AF37: N/A | AG37: 63600000 | AH37: 41.35 | AI37: 27.7 | AJ37: 27.7 | AK37: SW DEV C1 | AL37: SW DEV C1 | AM37: Yes | AN37: 2.2 | AO37: Yes | AP37: 830 | AQ37: Yes | AR37: 1395 | AS37: No | AU37: No | AW37: No | BY37: =IF(COUNTIF('Data Upload-prod'!E:E,F37)=0,"Missing","Exist") -> Exist
A38: 41974 | B38: N/A | C38: SHELL | D38: SB | E38: SOUTH FURIOUS | F38: SF-16S2 | G38: APPRAISAL CUM DEV/DEVELOPMENT | H38: WEST VIGILANT | I38: JACK UP | J38: 49.07 | K38: 1471.5 | L38: 1122.52 | M38: N/A | N38: N/A | O38: N/A | P38: N/A | Q38: 113600000 | R38: 56.8 | S38: SIDETRACK | T38: N/A | U38: N/A | V38: 42035 | W38: 42035 | X38: 42053 | Y38: 1397.9 | Z38: SHALLOW WATER | AA38: 1490.09 | AB38: 1134.72 | AC38: N/A | AD38: N/A | AE38: N/A | AF38: N/A | AG38: 36039203 | AH38: 69.5 | AI38: 2.74 | AJ38: 2.74 | AK38: No DMS category | AL38: No | AM38: No | AO38: No | AQ38: No | AS38: No | AU38: No | AW38: No | BY38: =IF(COUNTIF('Data Upload-prod'!E:E,F38)=0,"Missing","Exist") -> Exist
A39: 41935 | B39: 42115 | C39: EMEPMI | D39: PM | E39: TELOK | F39: TELOK-B4 | G39: APPRAISAL CUM DEV/DEVELOPMENT | H39: WEST LEDA | I39: JACK UP | J39: 63.6 | K39: 2746 | L39: 2134 | M39: N/A | N39: N/A | O39: N/A | P39: N/A | Q39: 25500000 | R39: 47.2 | S39: NO | T39: N/A | U39: DRY TREE | V39: 41953.375 | W39: 41952.312 | X39: 42075.708 | Y39: 2601.53 | Z39: SHALLOW WATER | AA39: 2710 | AB39: 2107.2 | AC39: N/A | AD39: N/A | AE39: N/A | AF39: N/A | AG39: 21232400 | AH39: 30.4 | AI39: 9.74 | AJ39: 9.74 | AK39: No DMS category | AL39: No | AM39: No | AO39: No | AQ39: No | AS39: No | AU39: No | AW39: No | BD39: 4.18 | BE39: 3161620.8 | BH39: SANDSTONE | BI39: NORMAL | BJ39: CASED HOLE GRAVEL PACK | BK39: NO | BL39: NO | BM39: 3-1/2" | BN39: 5.0 | BO39: DUAL | BP39: L80 13CR | BQ39: 2490 | BR39: True | BS39: NONE | BT39: L80 13CR | BU39: 9.5 | BV39: NACL | BW39: NO | BX39: NO | BY39: =IF(COUNTIF('Data Upload-prod'!E:E,F39)=0,"Missing","Exist") -> Exist
A40: 41855 | B40: 42145 | C40: EMEPMI | D40: PM | E40: TELOK | F40: TELOK-B6 | G40: APPRAISAL CUM DEV/DEVELOPMENT | H40: WEST LEDA | I40: JACK UP | J40: 63.6 | K40: 2370 | L40: 1160 | M40: N/A | N40: N/A | O40: N/A | P40: N/A | Q40: 25900000 | R40: 40.3 | S40: NO | T40: N/A | U40: N/A | V40: 41949.458 | W40: 41948 | X40: 42075.208 | Y40: 2332.53 | Z40: SHALLOW WATER | AA40: 2441 | AB40: 1175.89 | AC40: N/A | AD40: N/A | AE40: N/A | AF40: N/A | AG40: 21609800 | AH40: 28.44 | AI40: 5.41 | AJ40: 5.41 | AK40: No DMS category | AL40: No | AM40: No | AO40: No | AQ40: No | AS40: No | AU40: No | AW40: No | BY40: =IF(COUNTIF('Data Upload-prod'!E:E,F40)=0,"Missing","Exist") -> Exist
...

Sheet Data Upload-prod
A1: PIC | B1: Status | C1: ReportJournalId | D1: WellId | E1: WellName | F1: Id | G1: IsReport | H1: Type | I1: ContentType | J1: Size | K1: UploadAt | L1: CreatedBy | M1: CreatedAt | N1: UpdatedBy | O1: UpdatedAt | P1: IsSuccess | Q1: DeletedBy | R1: IsDeleted | S1: FileName | T1: FileName (ETL) | V1: FileSize | W1: Path | X1: Availability
A2: Mursyid | B2: Yes | C2: 8AA810DC-2B3D-46BD-9491-9F16C59EE792 | D2: DE852130-D7D6-4B59-A0FB-001DEBCCE3EB | E2: SAMARANG-B123 | F2: C4BFE42D-6C6A-4722-8265-7492D0FEB38F | G2: 1 | H2: NOOP | I2: application/pdf | J2: NULL | K2: NULL | L2: NULL | M2: NULL | N2: NULL | O2: NULL | P2: 1 | Q2: NULL | R2: 0 | S2: SAMARANG-B123 NOOP.pdf | T2: SAMARANG-B123 NOOP.pdf | U2: =IF(S2=T2,"Yes","No") -> Yes | W2: Uploads\c4bfe42d-6c6a-4722-8265-7492d0feb38f.pdf | X2: =IF(COUNTIF('MyWells Drilling Comp'!F:F,E2)=0,"Missing","Exist") -> Exist
A3: Mursyid | B3: Yes | C3: 5FF025AE-E7FD-4902-ACDD-C7BA0594F8FE | D3: DE852130-D7D6-4B59-A0FB-001DEBCCE3EB | E3: SAMARANG-B123 | F3: 0A421437-1633-46AD-BC15-0B7E164DB2E2 | G3: 1 | H3: FWR | I3: application/pdf | J3: NULL | K3: NULL | L3: NULL | M3: NULL | N3: NULL | O3: NULL | P3: 1 | Q3: NULL | R3: 0 | S3: SAMARANG-B123 FWR.pdf | T3: SAMARANG-B123 FWR.pdf | U3: =IF(S3=T3,"Yes","No") -> Yes | W3: Uploads\0a421437-1633-46ad-bc15-0b7e164db2e2.pdf | X3: =IF(COUNTIF('MyWells Drilling Comp'!F:F,E3)=0,"Missing","Exist") -> Exist
A4: Mursyid | B4: Yes | C4: 5E04E6D7-8AFE-4D45-8E01-992A7CABFC22 | D4: 59815EB3-C163-450B-A924-00CD25EED857 | E4: HADRAH-1 | F4: F2A753FA-4F94-4E04-BA19-FD5DD3C20070 | G4: 1 | H4: FWR | I4: application/pdf | J4: NULL | K4: NULL | L4: NULL | M4: NULL | N4: NULL | O4: NULL | P4: 1 | Q4: NULL | R4: 0 | S4: Hadrah-1 Final Well Report_with attachments.pdf | T4: Hadrah-1 Final Well Report_with attachments.pdf | U4: =IF(S4=T4,"Yes","No") -> Yes | W4: Uploads\f2a753fa-4f94-4e04-ba19-fd5dd3c20070.pdf | X4: =IF(COUNTIF('MyWells Drilling Comp'!F:F,E4)=0,"Missing","Exist") -> Exist
A5: Mursyid | B5: Yes | C5: 08E63DE3-4F92-467E-9934-5744194F510A | D5: 59815EB3-C163-450B-A924-00CD25EED857 | E5: HADRAH-1 | F5: 28E6B044-E20C-48C0-9464-8C0385877FCA | G5: 1 | H5: NOOP | I5: application/pdf | J5: NULL | K5: NULL | L5: NULL | M5: NULL | N5: NULL | O5: NULL | P5: 1 | Q5: NULL | R5: 0 | S5: Hadrah-1 NOOP.pdf | T5: Hadrah-1 NOOP.pdf | U5: =IF(S5=T5,"Yes","No") -> Yes | W5: Uploads\28e6b044-e20c-48c0-9464-8c0385877fca.pdf | X5: =IF(COUNTIF('MyWells Drilling Comp'!F:F,E5)=0,"Missing","Exist") -> Exist
A6: Mursyid | B6: Yes | C6: 9C582344-803A-4408-B364-165E54F1AC33 | D6: E2E37CDE-4762-4283-8993-00D4920B267D | E6: WD-A13 | F6: F1BD3C71-CE1A-4942-9D06-A028C51DD1D4 | G6: 1 | H6: NOOP | I6: application/pdf | J6: NULL | K6: NULL | L6: NULL | M6: NULL | N6: NULL | O6: NULL | P6: 1 | Q6: NULL | R6: 0 | S6: PMO3WDESWS14_WD-A13.pdf | T6: PMO3WDESWS14_WD-A13.pdf | U6: =IF(S6=T6,"Yes","No") -> Yes | W6: Uploads\f1bd3c71-ce1a-4942-9d06-a028c51dd1d4.pdf | X6: =IF(COUNTIF('MyWells Drilling Comp'!F:F,E6)=0,"Missing","Exist") -> Exist
A7: Mursyid | B7: Yes | C7: A7CCB483-E533-4705-9ABC-E4170E4CB088 | D7: E2E37CDE-4762-4283-8993-00D4920B267D | E7: WD-A13 | F7: 908E1F2C-E3D8-4F44-8EF6-1EC2D56677F4 | G7: 1 | H7: FWR | I7: application/pdf | J7: NULL | K7: NULL | L7: NULL | M7: NULL | N7: NULL | O7: NULL | P7: 1 | Q7: NULL | R7: 0 | S7: PMO3WDESWS49_WD-A13.pdf | T7: PMO3WDESWS49_WD-A13.pdf | U7: =IF(S7=T7,"Yes","No") -> Yes | W7: Uploads\908e1f2c-e3d8-4f44-8ef6-1ec2d56677f4.pdf | X7: =IF(COUNTIF('MyWells Drilling Comp'!F:F,E7)=0,"Missing","Exist") -> Exist
A8: Mursyid | B8: Yes | C8: 2802568D-0803-40F3-8168-FC03FB34CE58 | D8: C844197F-4206-492F-9856-010FFE56793F | E8: SUMANDAK SELATAN-B16ST1 | F8: 963A123D-1A47-4F8E-A984-359B05959C6C | G8: 1 | H8: FWR | I8: application/pdf | J8: NULL | K8: NULL | L8: NULL | M8: NULL | N8: NULL | O8: NULL | P8: 1 | Q8: NULL | R8: 0 | S8: Petronas Final Well Report B16 ST2 rev 3.pdf | T8: Petronas Final Well Report B16 ST2 rev 3.pdf | U8: =IF(S8=T8,"Yes","No") -> Yes | W8: Uploads\963a123d-1a47-4f8e-a984-359b05959c6c.pdf | X8: =IF(COUNTIF('MyWells Drilling Comp'!F:F,E8)=0,"Missing","Exist") -> Exist
A9: Mursyid | B9: Yes | C9: 75C6ECC4-711E-4529-973B-64E4C3CE7ECB | D9: C844197F-4206-492F-9856-010FFE56793F | E9: SUMANDAK SELATAN-B16ST1 | F9: FB5E6977-EDDE-47A9-8D74-8CC0C45C66AD | G9: 1 | H9: NOOP | I9: application/pdf | J9: NULL | K9: NULL | L9: NULL | M9: NULL | N9: NULL | O9: NULL | P9: 1 | Q9: NULL | R9: 0 | S9: Sumandak Selatan B16 ST1 NOOP (FINAL).pdf | T9: Sumandak Selatan B16 ST1 NOOP (FINAL).pdf | U9: =IF(S9=T9,"Yes","No") -> Yes | W9: Uploads\fb5e6977-edde-47a9-8d74-8cc0c45c66ad.pdf | X9: =IF(COUNTIF('MyWells Drilling Comp'!F:F,E9)=0,"Missing","Exist") -> Exist
A10: Mursyid | B10: Yes | C10: 9E3730FF-FD4F-43C6-92A6-61045B607718 | D10: 1626FB0A-7458-414B-B820-015880FA6921 | E10: D21-A3 | F10: 5D18B9F3-4EA1-41F5-8B05-08B27AFA51CD | G10: 1 | H10: FWR | I10: application/pdf | J10: NULL | K10: NULL | L10: NULL | M10: NULL | N10: NULL | O10: NULL | P10: 1 | Q10: NULL | R10: 0 | S10: SKO3D21-WS47_D21-A3.pdf | T10: SKO3D21-WS47_D21-A3.pdf | U10: =IF(S10=T10,"Yes","No") -> Yes | W10: Uploads\5d18b9f3-4ea1-41f5-8b05-08b27afa51cd.pdf | X10: =IF(COUNTIF('MyWells Drilling Comp'!F:F,E10)=0,"Missing","Exist") -> Exist
A11: Mursyid | B11: Yes | C11: 06D82BA6-E854-4453-BE79-1882F19FFFE1 | D11: 1626FB0A-7458-414B-B820-015880FA6921 | E11: D21-A3 | F11: 6725064A-4CAD-40BA-A806-3A8CB1AF511F | G11: 1 | H11: NOOP | I11: application/pdf | J11: NULL | K11: NULL | L11: NULL | M11: NULL | N11: NULL | O11: NULL | P11: 1 | Q11: NULL | R11: 0 | S11: SKO3D21-WS50_D21-A3.pdf | T11: SKO3D21-WS50_D21-A3.pdf | U11: =IF(S11=T11,"Yes","No") -> Yes | W11: Uploads\6725064a-4cad-40ba-a806-3a8cb1af511f.pdf | X11: =IF(COUNTIF('MyWells Drilling Comp'!F:F,E11)=0,"Missing","Exist") -> Exist
A12: Mursyid | B12: Yes | C12: 692DEF30-8075-4FFB-A121-D02B881F214C | D12: 024D8DAB-F83E-4087-8CA7-016D8C5687AC | E12: KMSE-A1 | F12: E02CC16F-4304-4215-9107-34A100D9B785 | G12: 1 | H12: FWR | I12: application/pdf | J12: NULL | K12: NULL | L12: NULL | M12: NULL | N12: NULL | O12: NULL | P12: 1 | Q12: NULL | R12: 0 | S12: KMSE-A1-FWR.pdf | U12: =IF(S12=T12,"Yes","No") -> No | W12: Uploads\e02cc16f-4304-4215-9107-34a100d9b785.pdf | X12: =IF(COUNTIF('MyWells Drilling Comp'!F:F,E12)=0,"Missing","Exist") -> Exist
A13: Mursyid | B13: Yes | C13: 8FD94B8F-6F3E-458C-8D62-DD64F3CCB550 | D13: 024D8DAB-F83E-4087-8CA7-016D8C5687AC | E13: KMSE-A1 | F13: C1707397-8860-41BE-811B-55766483FDD8 | G13: 1 | H13: NOOP | I13: application/pdf | J13: NULL | K13: NULL | L13: NULL | M13: NULL | N13: NULL | O13: NULL | P13: 1 | Q13: NULL | R13: 0 | S13: KMSE A1_NOOP_2013_SK.pdf | T13: KMSE A1_NOOP_2013_SK.pdf | U13: =IF(S13=T13,"Yes","No") -> Yes | W13: Uploads\c1707397-8860-41be-811b-55766483fdd8.pdf | X13: =IF(COUNTIF('MyWells Drilling Comp'!F:F,E13)=0,"Missing","Exist") -> Exist
A14: Mursyid | B14: Yes | C14: FB8E0A8B-2E89-4B43-846F-FED38257C652 | D14: 5E15C965-E999-48C8-9069-01877D2A515F | E14: DULANG-D10ST1 (WI) | F14: 49B1239B-C9CC-44EC-A244-675514BD5F66 | G14: 1 | H14: FWR | I14: application/pdf | J14: NULL | K14: NULL | L14: NULL | M14: NULL | N14: NULL | O14: NULL | P14: 1 | Q14: NULL | R14: 0 | S14: DULANG-D10ST1 FWR.pdf | T14: DULANG-D10ST1 FWR.pdf | U14: =IF(S14=T14,"Yes","No") -> Yes | W14: Uploads\49b1239b-c9cc-44ec-a244-675514bd5f66.pdf | X14: =IF(COUNTIF('MyWells Drilling Comp'!F:F,E14)=0,"Missing","Exist") -> Exist
A15: Mursyid | B15: Yes | C15: C33F0AD0-0E2D-4FF6-B493-128A3680FADA | D15: 5E15C965-E999-48C8-9069-01877D2A515F | E15: DULANG-D10ST1 (WI) | F15: 32AB8B2B-48C2-4149-BF0C-581722E48E7F | G15: 1 | H15: NOOP | I15: application/pdf | J15: NULL | K15: NULL | L15: NULL | M15: NULL | N15: NULL | O15: NULL | P15: 1 | Q15: NULL | R15: 0 | S15: Dulang EMP D10ST1 (W1) - WI Final Submission to MPM.pdf | T15: Dulang EMP D10ST1 (W1) - WI Final Submission to MPM.pdf | U15: =IF(S15=T15,"Yes","No") -> Yes | W15: Uploads\32ab8b2b-48c2-4149-bf0c-581722e48e7f.pdf | X15: =IF(COUNTIF('MyWells Drilling Comp'!F:F,E15)=0,"Missing","Exist") -> Exist
A16: Mursyid | B16: Yes | C16: 1BA09680-BDD0-4F15-8448-4F3976417F1C | D16: 16119A4E-13CE-49EC-953A-023BB4B36713 | E16: BENTARA-A4 | F16: EB9CF70E-C7D9-4DD3-B329-6C976EE0E827 | G16: 1 | H16: FWR | I16: application/pdf | J16: NULL | K16: NULL | L16: NULL | M16: NULL | N16: NULL | O16: NULL | P16: 1 | Q16: NULL | R16: 0 | S16: Bentara-A4 Final Well Report_.pdf | T16: Bentara-A4 Final Well Report_.pdf | U16: =IF(S16=T16,"Yes","No") -> Yes | W16: Uploads\eb9cf70e-c7d9-4dd3-b329-6c976ee0e827.pdf | X16: =IF(COUNTIF('MyWells Drilling Comp'!F:F,E16)=0,"Missing","Exist") -> Exist
A17: Mursyid | B17: Yes | C17: 9492E4B7-C6B1-47ED-BC1D-D8F7EBF4CB75 | D17: 16119A4E-13CE-49EC-953A-023BB4B36713 | E17: BENTARA-A4 | F17: 71E2CFC6-F653-4CEB-93A7-3BE85AF92416 | G17: 1 | H17: NOOP | I17: application/pdf | J17: NULL | K17: NULL | L17: NULL | M17: NULL | N17: NULL | O17: NULL | P17: 1 | Q17: NULL | R17: 0 | S17: NOOP Bentara-A4_Signed_rev01.pdf | T17: NOOP Bentara-A4_Signed_rev01.pdf | U17: =IF(S17=T17,"Yes","No") -> Yes | W17: Uploads\71e2cfc6-f653-4ceb-93a7-3be85af92416.pdf | X17: =IF(COUNTIF('MyWells Drilling Comp'!F:F,E17)=0,"Missing","Exist") -> Exist
A18: Mursyid | B18: Yes | C18: 9325DC20-1891-4F21-8CFB-1E9D80830BAE | D18: 853C8EE9-7432-41BC-A655-024326B964D0 | E18: OPHIR-A3 | F18: 9B2021DE-FE26-4D41-A86D-3CF9D89BECC6 | G18: 1 | H18: FWR | I18: application/pdf | J18: NULL | K18: NULL | L18: NULL | M18: NULL | N18: NULL | O18: NULL | P18: 1 | Q18: NULL | R18: 0 | S18: OPHIR-A3 EOWR [FINAL].pdf | T18: OPHIR-A3 EOWR [FINAL].pdf | U18: =IF(S18=T18,"Yes","No") -> Yes | W18: Uploads\9b2021de-fe26-4d41-a86d-3cf9d89becc6.pdf | X18: =IF(COUNTIF('MyWells Drilling Comp'!F:F,E18)=0,"Missing","Exist") -> Exist
A19: Mursyid | B19: Yes | C19: 8226D588-54E3-4054-8DA7-A7E421DFE6A2 | D19: 853C8EE9-7432-41BC-A655-024326B964D0 | E19: OPHIR-A3 | F19: CD1CD901-F56C-44B5-94C6-6B34D541C2C9 | G19: 1 | H19: NOOP | I19: application/pdf | J19: NULL | K19: NULL | L19: NULL | M19: NULL | N19: NULL | O19: NULL | P19: 1 | Q19: NULL | R19: 0 | S19: NOOP Ophir-A3 Azry.pdf | T19: NOOP Ophir-A3 Azry.pdf | U19: =IF(S19=T19,"Yes","No") -> Yes | W19: Uploads\cd1cd901-f56c-44b5-94c6-6b34d541c2c9.pdf | X19: =IF(COUNTIF('MyWells Drilling Comp'!F:F,E19)=0,"Missing","Exist") -> Exist
A20: Mursyid | B20: Yes | C20: EA7128A4-2AFA-484B-BA6F-2B537FD225C6 | D20: 90ABE30C-CFE5-4B96-AD6A-029E6883FD37 | E20: D18-208A | F20: 21EBEC4F-0D88-464F-8D4A-162F5407907F | G20: 1 | H20: NOOP | I20: application/pdf | J20: NULL | K20: NULL | L20: NULL | M20: NULL | N20: NULL | O20: NULL | P20: 1 | Q20: NULL | R20: 0 | S20: SKO3D18-GL29_D18_208A.pdf | T20: SKO3D18-GL29_D18_208A.pdf | U20: =IF(S20=T20,"Yes","No") -> Yes | W20: Uploads\21ebec4f-0d88-464f-8d4a-162f5407907f.pdf | X20: =IF(COUNTIF('MyWells Drilling Comp'!F:F,E20)=0,"Missing","Exist") -> Exist
A21: Mursyid | B21: Yes | C21: 41F76A10-EB81-4CD3-911F-4F373500EE57 | D21: 90ABE30C-CFE5-4B96-AD6A-029E6883FD37 | E21: D18-208A | F21: AA2252D7-590F-43EE-9CF7-88DBD8E45919 | G21: 1 | H21: FWR | I21: application/pdf | J21: NULL | K21: NULL | L21: NULL | M21: NULL | N21: NULL | O21: NULL | P21: 1 | Q21: NULL | R21: 0 | S21: D-18 208 A Final Well Report 208A-OP6 Signed.pdf | T21: D-18 208 A Final Well Report 208A-OP6 Signed.pdf | U21: =IF(S21=T21,"Yes","No") -> Yes | W21: Uploads\aa2252d7-590f-43ee-9cf7-88dbd8e45919.pdf | X21: =IF(COUNTIF('MyWells Drilling Comp'!F:F,E21)=0,"Missing","Exist") -> Exist
A22: Mursyid | B22: Yes | C22: 1B0340CC-880F-4F44-BADA-9A2397381E8F | D22: 56C05C64-A50C-4B2A-802E-02D40CDEE213 | E22: BUNGA KANGSAR-1 | F22: 37AD2524-37E7-4E17-9815-CFB73152015E | G22: 1 | H22: NOOP | I22: application/pdf | J22: NULL | K22: NULL | L22: NULL | M22: NULL | N22: NULL | O22: NULL | P22: 1 | Q22: NULL | R22: 0 | S22: Bunga Kangsar-1 NOOP.pdf | T22: Bunga Kangsar-1 NOOP.pdf | U22: =IF(S22=T22,"Yes","No") -> Yes | W22: Uploads\37ad2524-37e7-4e17-9815-cfb73152015e.pdf | X22: =IF(COUNTIF('MyWells Drilling Comp'!F:F,E22)=0,"Missing","Exist") -> Exist
A23: Mursyid | B23: Yes | C23: 72F451A6-55FD-4566-A61E-D7B8A3E61EC5 | D23: 56C05C64-A50C-4B2A-802E-02D40CDEE213 | E23: BUNGA KANGSAR-1 | F23: 639814D0-FA66-46D5-AC1E-3DA444319404 | G23: 1 | H23: FWR | I23: application/pdf | J23: NULL | K23: NULL | L23: NULL | M23: NULL | N23: NULL | O23: NULL | P23: 1 | Q23: NULL | R23: 0 | S23: Bunga Kangsar-1 n ST1 EoWR - Signed.pdf | T23: Bunga Kangsar-1 n ST1 EoWR - Signed.pdf | U23: =IF(S23=T23,"Yes","No") -> Yes | W23: Uploads\639814d0-fa66-46d5-ac1e-3da444319404.pdf | X23: =IF(COUNTIF('MyWells Drilling Comp'!F:F,E23)=0,"Missing","Exist") -> Exist
A24: Mursyid | B24: Yes | C24: D9D333FA-0B6F-4C84-9F21-B6BEF1D5C00A | D24: A1A933A4-9D40-420C-89FE-0323004F37C0 | E24: F14-107 | F24: 907F858F-735B-460C-89E8-77A3C270C6E8 | G24: 1 | H24: FWR | I24: application/pdf | J24: NULL | K24: NULL | L24: NULL | M24: NULL | N24: NULL | O24: NULL | P24: 1 | Q24: NULL | R24: 0 | S24: F14-107 FDCR.pdf | T24: F14-107 FDCR.pdf | U24: =IF(S24=T24,"Yes","No") -> Yes | W24: Uploads\907f858f-735b-460c-89e8-77a3c270c6e8.pdf | X24: =IF(COUNTIF('MyWells Drilling Comp'!F:F,E24)=0,"Missing","Exist") -> Exist
... A30: Mursyid | B30: Yes | C30: 5ECF0704-5652-44A8-8C70-6F0D2DB220C8 | D30: 7B04A1F3-6C63-458A-9DD7-05338CA76373 | E30: BESTARI-3 | F30: C50ECEED-EA8C-47EA-BEF8-EE588E59224B | G30: 1 | H30: FWR | I30: application/pdf | J30: NULL | K30: NULL | L30: NULL | M30: NULL | N30: NULL | O30: NULL | P30: 1 | Q30: NULL | R30: 0 | S30: JXN-DWR-DRG-6-TCR-011-Rev.03 (FINAL)_Bestari-3_EOWR with Appendix.pdf | T30: JXN-DWR-DRG-6-TCR-011-Rev.03 (FINAL)_Bestari-3_EOWR with Appendix.pdf | U30: =IF(S30=T30,"Yes","No") -> Yes | W30: Uploads\c50eceed-ea8c-47ea-bef8-ee588e59224b.pdf | X30: =IF(COUNTIF('MyWells Drilling Comp'!F:F,E30)=0,"Missing","Exist") -> Exist
A31: Mursyid | B31: Yes | C31: 11B07E50-C2B0-47A7-AF35-58FB019495F4 | D31: 7B04A1F3-6C63-458A-9DD7-05338CA76373 | E31: BESTARI-3 | F31: A4F54413-7861-408B-A6B1-B32A431128B5 | G31: 1 | H31: NOOP | I31: application/pdf | J31: NULL | K31: NULL | L31: NULL | M31: NULL | N31: NULL | O31: NULL | P31: 1 | Q31: NULL | R31: 0 | S31: Bestari-3 NOOP.pdf | U31: =IF(S31=T31,"Yes","No") -> No | W31: Uploads\a4f54413-7861-408b-a6b1-b32a431128b5.pdf | X31: =IF(COUNTIF('MyWells Drilling Comp'!F:F,E31)=0,"Missing","Exist") -> Exist
A32: Mursyid | B32: Yes | C32: 8C019F30-392E-4DCE-8632-76BD7BCA9905 | D32: DD10A50F-B668-4097-82FB-062F0BEFFFBF | E32: BRWA-17 | F32: A074076C-196B-4972-8DB3-E3464433F3CD | G32: 1 | H32: NOOP | I32: application/pdf | J32: NULL | K32: NULL | L32: NULL | M32: NULL | N32: NULL | O32: NULL | P32: 1 | Q32: NULL | R32: 0 | S32: NOOP BRWA17.pdf | T32: NOOP BRWA17.pdf | U32: =IF(S32=T32,"Yes","No") -> Yes | W32: Uploads\a074076c-196b-4972-8db3-e3464433f3cd.pdf | X32: =IF(COUNTIF('MyWells Drilling Comp'!F:F,E32)=0,"Missing","Exist") -> Exist
A33: Mursyid | B33: Yes | C33: 1E45B69E-C78A-400B-8216-783CD6D389D6 | D33: DD10A50F-B668-4097-82FB-062F0BEFFFBF | E33: BRWA-17 | F33: 7DB6A500-455C-4031-9D46-C7558BAF9B13 | G33: 1 | H33: FWR | I33: application/pdf | J33: NULL | K33: NULL | L33: NULL | M33: NULL | N33: NULL | O33: NULL | P33: 1 | Q33: NULL | R33: 0 | S33: VPSB-BEF3-DRL-WWR-0003 BRWA-17 Final Well Report Rev.1.pdf | T33: VPSB-BEF3-DRL-WWR-0003 BRWA-17 Final Well Report Rev.1.pdf | U33: =IF(S33=T33,"Yes","No") -> Yes | W33: Uploads\7db6a500-455c-4031-9d46-c7558baf9b13.pdf | X33: =IF(COUNTIF('MyWells Drilling Comp'!F:F,E33)=0,"Missing","Exist") -> Exist
A34: Mursyid | B34: Yes | C34: 0384D4C4-7AFC-463A-9878-1A22D1A11744 | D34: 8C9D4BBF-95D2-490B-82A4-0652024B90A1 | E34: PESA-02 | F34: C45EF873-F468-42E3-ACC8-6A5D3BC1AE7E | G34: 1 | H34: NOOP | I34: application/pdf | J34: NULL | K34: NULL | L34: NULL | M34: NULL | N34: NULL | O34: NULL | P34: 1 | Q34: NULL | R34: 0 | S34: PEMANIS PESA-1, PESA-2, PESA-3 and PESA-4 NOOP Revised.pdf | T34: PEMANIS PESA-1, PESA-2, PESA-3 and PESA-4 NOOP Revised.pdf | U34: =IF(S34=T34,"Yes","No") -> Yes | W34: Uploads\c45ef873-f468-42e3-acc8-6a5d3bc1ae7e.pdf | X34: =IF(COUNTIF('MyWells Drilling Comp'!F:F,E34)=0,"Missing","Exist") -> Exist
A35: Mursyid | B35: Yes | C35: 2A125C18-480B-468B-9731-DF24D0785D58 | D35: 8C9D4BBF-95D2-490B-82A4-0652024B90A1 | E35: PESA-02 | F35: 9C463DFF-0A22-4B77-B88A-B2C7364349BD | G35: 1 | H35: FWR | I35: application/pdf | J35: NULL | K35: NULL | L35: NULL | M35: NULL | N35: NULL | O35: NULL | P35: 1 | Q35: NULL | R35: 0 | S35: PESA-2 EOWR FINAL (APPROVED).pdf | T35: PESA-2 EOWR FINAL (APPROVED).pdf | U35: =IF(S35=T35,"Yes","No") -> Yes | W35: Uploads\9c463dff-0a22-4b77-b88a-b2c7364349bd.pdf | X35: =IF(COUNTIF('MyWells Drilling Comp'!F:F,E35)=0,"Missing","Exist") -> Exist
A36: Mursyid | B36: Yes | C36: AE4C98D3-7731-43E4-9834-7C32980803E1 | D36: D2179E06-3BAA-4D3C-A29F-06A51D43ACD6 | E36: PUTERI A-05 | F36: 6BD835FF-3184-41A0-8603-42F41E09C4AC | G36: 1 | H36: FWR | I36: application/pdf | J36: NULL | K36: NULL | L36: NULL | M36: NULL | N36: NULL | O36: NULL | P36: 1 | Q36: NULL | R36: 0 | S36: Puteri A-5 End of Well Report - FINAL - signed.pdf | T36: Puteri A-5 End of Well Report - FINAL - signed.pdf | U36: =IF(S36=T36,"Yes","No") -> Yes | W36: Uploads\6bd835ff-3184-41a0-8603-42f41e09c4ac.pdf | X36: =IF(COUNTIF('MyWells Drilling Comp'!F:F,E36)=0,"Missing","Exist") -> Exist
A37: Mursyid | B37: Yes | C37: C0BB2163-87F8-429B-8087-9406A91951E7 | D37: D2179E06-3BAA-4D3C-A29F-06A51D43ACD6 | E37: PUTERI A-05 | F37: B9AE50FE-7783-41DF-8B4F-E1FE94897BD0 | G37: 1 | H37: NOOP | I37: application/pdf | J37: NULL | K37: NULL | L37: NULL | M37: NULL | N37: NULL | O37: NULL | P37: 1 | Q37: NULL | R37: 0 | S37: PMO3PTRIGL04_PUTERI-A05_SOMV.pdf | T37: PMO3PTRIGL04_PUTERI-A05_SOMV.pdf | U37: =IF(S37=T37,"Yes","No") -> Yes | W37: Uploads\b9ae50fe-7783-41df-8b4f-e1fe94897bd0.pdf | X37: =IF(COUNTIF('MyWells Drilling Comp'!F:F,E37)=0,"Missing","Exist") -> Exist
A38: Mursyid | B38: Yes | C38: 97BFA078-E9FD-4462-9F8D-A8E6750D7282 | D38: E06E5C20-4565-4AC3-BB56-06EBD3970E37 | E38: BKC-17 | F38: BFB119B0-5FCF-4894-AD29-F7B01946E94E | G38: 1 | H38: NOOP | I38: application/pdf | J38: NULL | K38: NULL | L38: NULL | M38: NULL | N38: NULL | O38: NULL | P38: 1 | Q38: NULL | R38: 0 | S38: PMO3BKWAGL71_BKC-17ST1(C).pdf | T38: PMO3BKWAGL71_BKC-17ST1(C).pdf | U38: =IF(S38=T38,"Yes","No") -> Yes | W38: Uploads\bfb119b0-5fcf-4894-ad29-f7b01946e94e.pdf | X38: =IF(COUNTIF('MyWells Drilling Comp'!F:F,E38)=0,"Missing","Exist") -> Exist
A39: Mursyid | B39: Yes | C39: 104C9AFD-33A2-4DDB-B821-5AB3E835C9C1 | D39: E06E5C20-4565-4AC3-BB56-06EBD3970E37 | E39: BKC-17 | F39: CA34D36C-1813-449B-B2C8-09EACF5E947A | G39: 1 | H39: FWR | I39: application/pdf | J39: NULL | K39: NULL | L39: NULL | M39: NULL | N39: NULL | O39: NULL | P39: 1 | Q39: NULL | R39: 0 | S39: PMO3BKWAWSB5_BKC-17ST1(C).pdf | T39: PMO3BKWAWSB5_BKC-17ST1(C).pdf | U39: =IF(S39=T39,"Yes","No") -> Yes | W39: Uploads\ca34d36c-1813-449b-b2c8-09eacf5e947a.pdf | X39: =IF(COUNTIF('MyWells Drilling Comp'!F:F,E39)=0,"Missing","Exist") -> Exist
A40: Mursyid | B40: Yes | C40: B1BA5BF3-8952-4573-8A97-76564FD873F4 | D40: 90978F74-C776-46A8-B2CC-06FF8CB0ED05 | E40: BERANTAI WEST-1 | F40: A29CBF93-5C02-47E9-B051-126315B08A52 | G40: 1 | H40: NOOP | I40: application/pdf | J40: NULL | K40: NULL | L40: NULL | M40: NULL | N40: NULL | O40: NULL | P40: 1 | Q40: NULL | R40: 0 | S40: NOOP Berantai West.pdf | T40: NOOP Berantai West.pdf | U40: =IF(S40=T40,"Yes","No") -> Yes | W40: Uploads\a29cbf93-5c02-47e9-b051-126315b08a52.pdf | X40: =IF(COUNTIF('MyWells Drilling Comp'!F:F,E40)=0,"Missing","Exist") -> Exist
A41: Mursyid | B41: Yes | C41: 9A7DA3BA-3772-40F9-BEEE-C01F0ACC01A9 | D41: 90978F74-C776-46A8-B2CC-06FF8CB0ED05 | E41: BERANTAI WEST-1 | F41: 821ADA6E-4271-46F0-BD36-654B2A723C91 | G41: 1 | H41: FWR | I41: application/pdf | J41: NULL | K41: NULL | L41: NULL | M41: NULL | N41: NULL | O41: NULL | P41: 1 | Q41: NULL | R41: 0 | S41: BRW-1 Final Well Report 2018-Final.pdf | T41: BRW-1 Final Well Report 2018-Final.pdf | U41: =IF(S41=T41,"Yes","No") -> Yes | W41: Uploads\821ada6e-4271-46f0-bd36-654b2a723c91.pdf | X41: =IF(COUNTIF('MyWells Drilling Comp'!F:F,E41)=0,"Missing","Exist") -> Exist
A42: Mursyid | B42: Yes | C42: 7306B53A-D376-4F0F-B2DF-5E069DCA04F3 | D42: E58C22EA-C774-4ED6-8796-072482B46DCD | E42: TOMAN-1 | F42: 10EB5179-8327-4EA8-BF91-814D97BAEE2F | G42: 1 | H42: FWR | I42: application/pdf | J42: NULL | K42: NULL | L42: NULL | M42: NULL | N42: NULL | O42: NULL | P42: 1 | Q42: NULL | R42: 0 | S42: SKO3TMANWS03_TOMAN-1.pdf | T42: SKO3TMANWS03_TOMAN-1.pdf | U42: =IF(S42=T42,"Yes","No") -> Yes | W42: Uploads\10eb5179-8327-4ea8-bf91-814d97baee2f.pdf | X42: =IF(COUNTIF('MyWells Drilling Comp'!F:F,E42)=0,"Missing","Exist") -> Exist
A43: Mursyid | B43: Yes | C43: 7B507B7F-245C-4CC5-8E66-94365A3CE471 | D43: E58C22EA-C774-4ED6-8796-072482B46DCD | E43: TOMAN-1 | F43: 10B4BC09-5717-4652-825E-307AD6235D4B | G43: 1 | H43: NOOP | I43: application/pdf | J43: NULL | K43: NULL | L43: NULL | M43: NULL | N43: NULL | O43: NULL | P43: 1 | Q43: NULL | R43: 0 | S43: SKO3TMANWS01_TOMAN-1.pdf | T43: SKO3TMANWS01_TOMAN-1.pdf | U43: =IF(S43=T43,"Yes","No") -> Yes | W43: Uploads\10b4bc09-5717-4652-825e-307ad6235d4b.pdf | X43: =IF(COUNTIF('MyWells Drilling Comp'!F:F,E43)=0,"Missing","Exist") -> Exist
A44: Mursyid | B44: Yes | C44: FB510231-D3EB-41AC-8A62-1B8432AD1D76 | D44: 70EE8F9B-20C5-4567-9461-072BFA4D3F21 | E44: TELOK-B7 | F44: 97922E5C-16DD-4872-94E9-472221233477 | G44: 1 | H44: FWR | I44: application/pdf | J44: NULL | K44: NULL | L44: NULL | M44: NULL | N44: NULL | O44: NULL | P44: 1 | Q44: NULL | R44: 0 | S44: Telok B7 Final Well Report (MPM Submission).pdf | T44: Telok B7 Final Well Report (MPM Submission).pdf | U44: =IF(S44=T44,"Yes","No") -> Yes | W44: Uploads\97922e5c-16dd-4872-94e9-472221233477.pdf | X44: =IF(COUNTIF('MyWells Drilling Comp'!F:F,E44)=0,"Missing","Exist") -> Exist
A45: Mursyid | B45: Yes | C45: 1F5C693A-2AD4-4D1F-A9B5-14B41E74A568 | D45: 70EE8F9B-20C5-4567-9461-072BFA4D3F21 | E45: TELOK-B7 | F45: 26E9326C-9339-4D10-B1DE-FF5DF864DC8F | G45: 1 | H45: NOOP | I45: application/pdf | J45: NULL | K45: NULL | L45: NULL | M45: NULL | N45: NULL | O45: NULL | P45: 1 | Q45: NULL | R45: 0 | S45: PMO3TELOWS58_TELOK-B7.pdf | U45: =IF(S45=T45,"Yes","No") -> No | W45: Uploads\26e9326c-9339-4d10-b1de-ff5df864dc8f.pdf | X45: =IF(COUNTIF('MyWells Drilling Comp'!F:F,E45)=0,"Missing","Exist") -> Exist
...
